{"name": "test_another_failing", "status": "failed", "statusDetails": {"message": "AssertionError: assert 1 == 2", "trace": "@pytest.mark.development\n    @pytest.mark.production\n    def test_another_failing():\n>       assert 1==2\nE       assert 1 == 2\n\ntests\\users\\test_users.py:40: AssertionError"}, "start": 1677606257036, "stop": 1677606257036, "uuid": "99617199-7a38-4ef9-8007-afc97f36a1d2", "historyId": "330b43461714ac8fd50aa4248bd6088b", "testCaseId": "5ea884e787ac25260657196d449877fa", "fullName": "tests.users.test_users#test_another_failing", "labels": [{"name": "tag", "value": "production"}, {"name": "tag", "value": "development"}, {"name": "parentSuite", "value": "tests.users"}, {"name": "suite", "value": "test_users"}, {"name": "host", "value": "DESKTOP-GO0B47L"}, {"name": "thread", "value": "4020-MainThread"}, {"name": "framework", "value": "pytest"}, {"name": "language", "value": "cpython3"}, {"name": "package", "value": "tests.users.test_users"}]}