{"name": "test_getting_users_list", "status": "broken", "statusDetails": {"message": "pydantic.error_wrappers.ValidationError: 1 validation error for User\nname\n  value is not a valid integer (type=type_error.integer)", "trace": "get_users = <Response [200]>, make_number = 846\n\n    def test_getting_users_list(get_users, make_number):\n>       Response(get_users).assert_status_code(200).validate(User)\n\ntests\\users\\test_users.py:13: \n_ _ _ _ _ _ _ _ _ _ _ _ _ _ _ _ _ _ _ _ _ _ _ _ _ _ _ _ _ _ _ _ _ _ _ _ _ _ _ _ _ _ _ _ _ _ _ _ _ _ _ _ _ _ _ _ _ _ _ _ _ _ _ _ _ _ _ _ _ _ _ _ _ _ _ _ _ _ _ _ _ _ _ _ _ _ _ _ _ _ _ _ _ _ _ _ _ _ _ _ _ _ _ _ _ _ _ _ _ \nsrc\\baseclasses\\response.py:17: in validate\n    schema.parse_obj(item)\npydantic\\main.py:527: in pydantic.main.BaseModel.parse_obj\n    ???\n_ _ _ _ _ _ _ _ _ _ _ _ _ _ _ _ _ _ _ _ _ _ _ _ _ _ _ _ _ _ _ _ _ _ _ _ _ _ _ _ _ _ _ _ _ _ _ _ _ _ _ _ _ _ _ _ _ _ _ _ _ _ _ _ _ _ _ _ _ _ _ _ _ _ _ _ _ _ _ _ _ _ _ _ _ _ _ _ _ _ _ _ _ _ _ _ _ _ _ _ _ _ _ _ _ _ _ _ _ \n\n>   ???\nE   pydantic.error_wrappers.ValidationError: 1 validation error for User\nE   name\nE     value is not a valid integer (type=type_error.integer)\n\npydantic\\main.py:342: ValidationError"}, "start": 1677607607772, "stop": 1677607607774, "uuid": "d5c78d25-bbe0-4bc8-ad9c-da1d353932e4", "historyId": "a8cd091c167665d3ed0d6c85ad20edfc", "testCaseId": "f3a35b35911a2442325e664a2ed974e0", "fullName": "tests.users.test_users#test_getting_users_list", "labels": [{"name": "parentSuite", "value": "tests.users"}, {"name": "suite", "value": "test_users"}, {"name": "host", "value": "DESKTOP-GO0B47L"}, {"name": "thread", "value": "7256-MainThread"}, {"name": "framework", "value": "pytest"}, {"name": "language", "value": "cpython3"}, {"name": "package", "value": "tests.users.test_users"}]}